Workbook
Name Print_Area: CashFlow!$B$1:$J$27
Name Print_Area: CostSold!$B$1:$I$21
Name Print_Area: CostTotal!$B$1:$G$19
Name Print_Area: Depreciate!$A$1:$K$9
Name Print_Area: FinPlan!$B$1:$G$10
Name Print_Area: Labour!$A$2:$F$33
Name Print_Area: Loans!$A$1:$F$96
Name Print_Area: npv!$B$3:$E$19
Name Print_Area: ProdPlan!$A$1:$I$58
Name Print_Area: ProfLoss!$A$1:$I$20
Name Print_Area: ProjCost!$B$1:$G$13
Name Print_Area: 'Share of Costs'!$B$2:$G$15
Name Print_Area: Taxes!$B$1:$K$17
Name Амортизац: #REF!
Name Дата_первой_выплаты: #REF!
Name Кредит_Б__в_USD: #REF!
Name Курс_0198: '[1]Поток реальных денег'!#REF!
Name Курс_USD: #REF!
Name Курс_USD: #REF!
Name Льготный_период: #REF!
Name Льготный_период: #REF!
Name Местные_продажи: #REF!
Name Объем: #REF!
Name Объем: #REF!
Name объем100: #REF!
Name объем100: #REF!
Name П\роцентная_ставка: #REF!
Name процент_на_маркетинг: #REF!
Name Срок_пользования_кредитом: #REF!
Name ст.пр.: #REF!
Name ЦенаЗаЕд.: #REF!
Name ценмест: #REF!
Name ценэксп: #REF!
Name Экспорт: #REF!

Sheet ВВОД
B15: Loyiha nomi:
B16: Parrandachilik
B17: Loyiha tashabbuskori:
B18: Bobur Аkbarov MCHJ
B19: Tadbirkor manzili:
B20: Namangan viloyati Kosonsoy tumani Chindovul 3-uy
B21: Xizmat ko‘rsatuvchi bank:
B22: Agrobank Kosonsoy
B23: STIR:
B24: 00231
B25: JSHSHIR:
B26: 30707942190044
... B87: 10

Sheet ProjCost
B2: LOYIHA QIYMATI | G2: 1-ILOVA
C3: % | D3: =+ВВОД!B23 -> STIR: | E3: BANK KREDITI, so'm | F3: Jami (so'm) | G3: Foiz hisobida
B4: Asosiy vositalarni sotib olish (mebel jihozlari) | D4: 0 | E4: =+ВВОД!B44 -> 100000000 | F4: =E4+D4 -> 100000000 | G4: =F4/$F$13 -> 0.98039216
B5: Asosiy vositalar | D5: =+ВВОД!B42 -> 50000000 | E5: 0 | F5: =D5 -> 50000000 | G5: =F5/F13 -> 0.49019608
B6: JAMI mablag'lar | D6: =+SUM(D4:D5) -> 0 | E6: =SUM(E4:E4) -> 0 | F6: =SUM(F4:F4) -> 100000000
B7: Aylanma kapital | D7: =SUM(D8:D8)+D9 -> 0 | E7: 0 | F7: =SUM(C7:D7) -> 0
B8: Aylanma kapital | D8: ='Share of Costs'!G8 -> 0 | E8: 0 | F8: =SUM(C8:D8) -> 0 | G8: =F8/$F$13 -> 0
B9: MOLIYAVIY XARAJATLAR | D9: ='Share of Costs'!G9 -> 0 | F9: =SUM(D9:D9) -> 0 | G9: =F9/$F$13 -> 0
B10: MOLIYAVIY XARAJATLAR | D10: =SUM(D11:D12) -> 2000000 | E10: =+E12 -> 0 | F10: =SUM(F11:F12) -> 2000000
B11: Sug'urta | D11: ='Share of Costs'!C11 -> 0 | E11: 0 | F11: =SUM(D11:D11) -> 0 | G11: =F11/$F$13 -> 0
B12: Kredit olish uchun boshqa xarajatlar | D12: ='Share of Costs'!C12 -> 2000000 | E12: 0 | F12: =SUM(D12:D12) -> 2000000 | G12: =F12/$F$13 -> 0.019607843
B13: LOYIHA QIYMATI | D13: =D7+D6+D10 -> 2000000 | E13: =+E4+E5 -> 100000000 | F13: =E13+D13 -> 102000000 | G13: =SUM(G4:G12) -> 1.4901961

Sheet FinPlan
B1: MOLIYAVIY REJA | G1: 2-ILOVA
D2: Milly valyuta, so'm | E2: Jami | F2: Struktura | G2: Foizda
B3: Kapital
B4: O'z mablag'lari | D4: ='Share of Costs'!C14 -> 52000000 | E4: =SUM(D4:D4) -> 52000000 | F4: =E4/E5 -> 1
B5: Jami kapital | D5: =SUM(D3:D4) -> 52000000 | E5: =SUM(E4:E4) -> 52000000 | G5: =E5/E10 -> 1
B6: Qarzga olingan mablag'lar
D7: =ProjCost!E6 -> 0 | E7: =D7 -> 0
B8: Jami qarz mablag'lari | D8: =SUM(D7:D7) -> 0 | E8: =SUM(E7:E7) -> 0 | G8: =E8/E10 -> 0
B9: Jami moliyalashtirish | E9: =E10-ProjCost!F13 -> -50000000
B10: Jami moliyalashtirish | D10: =D5+D8 -> 52000000 | E10: =E5+E8 -> 52000000 | G10: =G5+G8 -> 1
E11: =TODAY() -> 46119
C12: Финансирование от Стройкомплектсервис | D12: в долл.США | E12: Всего
B13: 1. | C13: Строительство и реконстр. сущ. здания | D13: 0 | E13: =D13+#REF! -> #REF!
B14: 2. | C14: Местное сырье | D14: 0 | E14: =D14+#REF! -> #REF!
B15: 3. | C15: Резерв на рабочий капитал | D15: 0 | E15: =D15+#REF! -> #REF!
C16: Всего от СКС | D16: =SUM(D13:D15) -> 0 | E16: =D16+#REF! -> #REF!
B17: Разница будет оплачена посредством предоставления кредита на сумму | E17: =#REF! -> #REF!
B18: сроком на 1-год с начала производства
C20: Финансирование от АО "Подъемник" | D20: в твердой валюте | E20: Всего
B21: 1. | C21: Здания и сооружения и инфраструктура к ним | D21: 0 | E21: =SUM(D21:D21) -> 0
C22: Всего от Подъемник | D22: =SUM(D21:D21) -> 0 | E22: =SUM(E21:E21) -> 0
C25: Финансирвание от МФК | D25: в твердой валюте | E25: Всего
B26: 1. | C26: Машины и оборудования | D26: =ProjCost!#REF! -> #REF! | E26: =D26+#REF! -> #REF!
B27: 2. | C27: Транспорт и страхование | D27: =ProjCost!#REF! -> #REF! | E27: =D27+#REF! -> #REF!
B28: 3. | C28: Монтаж и запуск | D28: =ProjCost!#REF! -> #REF! | E28: =D28+#REF! -> #REF!
B29: 4. | C29: Грузовая машина | D29: =ProjCost!#REF! -> #REF! | E29: =D29+#REF! -> #REF!
B30: 5. | C30: Охранная видео система | D30: =ProjCost!#REF! -> #REF! | E30: =D30+#REF! -> #REF!
B31: 6. | C31: Накладные расходы | D31: =ProjCost!#REF! -> #REF! | E31: =D31+#REF! -> #REF!
B32: 7. | C32: Вспомогательные материалы | D32: =ProjCost!#REF! -> #REF! | E32: =D32+#REF! -> #REF!
B33: 8. | C33: Запасные части | D33: =ProjCost!#REF! -> #REF! | E33: =D33+#REF! -> #REF!
B34: 9. | C34: Финансовые расходы | D34: =ProjCost!#REF!+ProjCost!#REF!+ProjCost!#REF!+ProjCost!#REF! -> #REF! | E34: =D34+#REF! -> #REF!
B35: 10. | C35: Резерв | D35: =ProjCost!#REF! -> #REF! | E35: =D35+#REF! -> #REF!
C36: Всего от МФК | D36: =SUM(D26:D35) -> #REF! | E36: =D36+#REF! -> #REF!
C38: Финансирование от Банка "Асака" (по кредитной линии МФК/Асака) | D38: в твердой валюте | E38: Всего
B39: 1. | C39: Машины и оборудования | D39: =ProjCost!#REF! -> #REF! | E39: =D39+#REF! -> #REF!
C40: Всего от Банка "Асака" | D40: =D39 -> #REF! | E40: =D40+#REF! -> #REF!
C42: Недостающая сумма | D42: в твердой валюте | E42: Всего
B43: 1. | C43: Проценты в инв. Период | D43: =ProjCost!#REF! -> #REF! | E43: =SUM(D43:D43) -> #REF!
B44: 2. | C44: Страхование залога | D44: 0 | E44: =SUM(D44:D44) -> 0
B45: 3. | C45: оформление залога | D45: 0 | E45: =SUM(D45:D45) -> 0
...

Sheet Share of Costs
B2: LOYIHA ISHTIROKCHILARI XARAJATLARINING ulushi | G2: 3-ILOVA
B3: Ko'rsatkichlar | C3: O'z mablag'lari | D3: Milliy valyutada, so'm | E3: Jami, summa | F3: =ProjCost!E3 -> BANK KREDITI, so'm | G3: Jami, summa
B4: =ProjCost!B4 -> Asosiy vositalarni sotib olish (mebel jihozlari) | C4: 0 | E4: 0 | F4: =ProjCost!E4 -> 100000000 | G4: =F4 -> 100000000
B5: Asosiy vositalar | C5: =ProjCost!D5 -> 50000000 | F5: 0 | G5: =C5 -> 50000000
B6: ASOSIY KAPITALLARNING TO'LIQ XARAJATLARI | C6: =C4+C5 -> 50000000 | E6: =#REF!+#REF!+E4 -> #REF! | F6: =F4 -> 100000000 | G6: =G4+G5 -> 150000000
B7: Aylanma kapital | C7: =C8+C9 -> 0 | E7: =E8+E9 -> 0 | F7: 0 | G7: =G8+G9 -> 0
B8: Aylanma kapital | C8: 0 | E8: 0 | F8: 0 | G8: =C8+E8 -> 0
B10: MOLIYAVIY XARAJATLAR | C10: =SUM(C11:C12) -> 2000000 | E10: =SUM(E12:E12) -> 0 | F10: 0 | G10: =E10+C10 -> 2000000
B11: Sug'urta | C11: 0 | E11: 0 | F11: 0 | G11: =C11+E11 -> 0
B12: Kredit olish uchun boshqa xarajatlar | C12: =(F13+F14)*1% -> 2000000 | E12: 0 | F12: 0 | G12: =C12+E12 -> 2000000
B13: TO'LIQ ISHLAB CHIQARISH XARAJATLARI | C13: =C7+C6+C10 -> 52000000 | E13: =E6+E7 -> #REF! | F13: =+F6 -> 100000000 | G13: =G7+G6+G10 -> 152000000
B14: JAMI BIRINCHI INVESTITSIYA XARAJATLARI | C14: =C13 -> 52000000 | E14: =E13 -> #REF! | F14: =F13 -> 100000000 | G14: =G13 -> 152000000

Sheet Depreciate
I2: 4-ILOVA
B3: AMORTIZATSIYA HISOBOTLARI
B4: Amortizatsiya ob'ektlari | C4: Xarajat (amortizatsiya qilinadigan baza) | D4: Amortizatsiya darajasi (%) | E4: 1-yil | F4: 2-yil | G4: 3-yil | H4: 4-yil | I4: 5-yil | J4: 6-yil | K4: 7-yil
B5: ='Share of Costs'!B5 -> Asosiy vositalar | C5: =+'Share of Costs'!G14 -> 152000000 | D5: 0.15 | E5: =+C5/7 -> 21714286 | F5: =+C5/7 -> 21714286 | G5: =+C5/7 -> 21714286 | H5: =+C5/7 -> 21714286 | I5: =C5/7 -> 21714286 | J5: =+C5/7 -> 21714286 | K5: =+C5/7 -> 21714286
B6: ='Share of Costs'!#REF! -> #REF! | C6: ='Share of Costs'!#REF! -> #REF! | D6: 0.15 | E6: =C6*D6 -> #REF! | F6: =E6 -> #REF! | G6: =F6 -> #REF! | H6: =G6 -> #REF! | I6: =H6 -> #REF! | J6: =I6 -> #REF! | K6: =J6 -> #REF!
B7: Jami amortizatsiya | C7: Х | D7: Х | E7: =E5 -> 21714286 | F7: =F5 -> 21714286 | G7: =G5 -> 21714286 | H7: =H5 -> 21714286 | I7: =I5 -> 21714286 | J7: =J5 -> 21714286 | K7: =K5 -> 21714286
B8: Yig'ilgan amortizatsiya | C8: Х | D8: Х | E8: =E7 -> 21714286 | F8: =F7+E8 -> 43428571 | G8: =G7+F8 -> 65142857 | H8: =H7+G8 -> 86857143 | I8: =I7+H8 -> 1.0857143e+08 | J8: =J7+I8 -> 1.3028571e+08 | K8: =K7+J8 -> 152000000

Sheet Labour
F2: 5-ILOVA
B3: ISH HAQI XARAJATLARI
B4: LAVOZIM | C4: SONI | D4: MAOSH (so'm) | E4: Oylik maosh (so'm) | F4: YILLIK maosh (so'm)
B5: Ma'muriyat
B6: Direktor | C6: =+ВВОД!B65 -> 1 | D6: =+ВВОД!B74 -> 1200000 | E6: =C6*D6 -> 1200000 | F6: =E6*12 -> 14400000
B7: JAMI | C7: =+C6 -> 1 | E7: =SUM(E6:E6) -> 1200000 | F7: =SUM(F6:F6) -> 14400000
B8: Ijtimoiy soliq | C8: 0.12 | D8: yillik ish haqi fondidan | F8: =F7*C8 -> 1728000
B9: JAMI | C9: =+C6 -> 1 | F9: =F7+F8 -> 16128000
B11: ISHCHI XODIM | C11: SONI | D11: MAOSH (so'm) | E11: Oylik maosh (so'm) | F11: YILLIK maosh (so'm)
B12: Ishchilar | C12: =+ВВОД!B67 -> 2 | D12: =+ВВОД!B72 -> 1500000 | E12: =+C12*D12 -> 3000000 | F12: =+E12*12 -> 36000000
B13: JAMI | C13: =+C12 -> 2 | E13: 3600000 | F13: =SUM(F12) -> 36000000
B14: Ijtimoiy soliq | C14: 0.12 | D14: yillik ish haqi fondidan | F14: =+F13*C14 -> 4320000
B15: JAMI | C15: =+C12 -> 2 | F15: =+F13+F14 -> 40320000
B16: YANGI IShChI XODIM
B17: Ishchi | C17: =+ВВОД!B69 -> 4 | D17: =+ВВОД!B76 -> 1500000 | E17: =+C17*D17 -> 6000000 | F17: =+E17*12 -> 72000000
B18: JAMI | C18: =+C17 -> 4 | E18: =SUM(E17) -> 6000000 | F18: =SUM(F17) -> 72000000
B19: Ijtimoiy soliq | C19: 0.12 | D19: yillik ish haqi fondidan | F19: =+F18*12% -> 8640000
B20: JAMI | C20: =+C17 -> 4 | F20: =+F18+F19 -> 80640000
B21: JAMI | C21: =+C9+C13+C18 -> 7 | F21: =+F9+F15+F20 -> 137088000
B23: FOYDALANISH XARAJATLARI
B25: BO'LIMLAR | C25: O'Lchov birligi | D25: YILLIK ISTE'MOL | E25: BIR BIRLIK NARXI (SO'M) | F25: YILLIK XARAJATLAR (SO'M)
B26: Elektr | C26: kvt/soat | D26: =+ВВОД!B81 -> 200 | E26: 900 | F26: =D26*E26 -> 180000
B27: Gaz | C27: kb/m | D27: =+ВВОД!B83 -> 10 | E27: 1000 | F27: =D27*E27 -> 10000
B28: Suv | C28: kb/m | D28: =+ВВОД!B85 -> 10 | E28: 4800 | F28: =D28*E28 -> 48000
B29: Oqava suv | C29: kb/m | D29: =+ВВОД!B87 -> 10 | E29: 1500 | F29: =D29*E29 -> 15000
B33: JAMI | C33: х | D33: х | E33: х | F33: =SUM(F26:F32) -> 253000

Sheet ProdPlan
B2: XIZMAT KO'RSATISH VA SOTISH REJASI | G2: 6-ILOVA
B3: NOMI | C3: Ishlab chiqarish hajmi dona/yil | D3: Xizmat ko'rsatish soni | E3: Jami xizmat ko'rsatish hajmi dona/yil | F3: O'rtacha sotuv narxi (so'm) | G3: 1 yillik savdo tushumi
B4: =+ВВОД!B56 -> 0 | C4: =+ВВОД!B58 -> 2000 | D4: =+ВВОД!B60 -> 51111 | E4: =C4*D4 -> 102222000 | F4: =+ВВОД!B62 -> 5000 | G4: =E4*F4 -> 511110000000
B13: SOTISH REJASI
B14: NOMI | C14: Birlik | D14: SOTISH HAJMI MAX. PROD. YILGA DASTUR, BIRLIKLAR | F14: O'rtacha xizmat narxi (so'm) | G14: Zaxiradagi tayyor mahsulot
B15: =+B4 -> 0 | C15: dona | D15: =E4 -> 102222000 | F15: =F4 -> 5000 | G15: 0
B16: Parrandachilik | C16: шт | D16: =E6*12 -> 0 | F16: =F6 -> 0 | G16: 0
B17: =B7 -> 0 | C17: шт | D17: =E7*12 -> 0 | F17: =F7 -> 0 | G17: 0
B18: "Bobur Аkbarov" MCHJ | C18: шт | D18: =E8*12 -> 0 | F18: =F8 -> 0 | G18: 0
B19: =B9 -> 0 | C19: шт | D19: =E9*12 -> 0 | F19: =F9 -> 0 | G19: 0
B23: KO'RSATGICHLAR | C23: =Depreciate!E4 -> 1-yil | D23: =Depreciate!F4 -> 2-yil | E23: =Depreciate!G4 -> 3-yil | F23: =Depreciate!H4 -> 4-yil | G23: =Depreciate!I4 -> 5-yil | H23: =Depreciate!J4 -> 6-yil | I23: =Depreciate!K4 -> 7-yil
B24: Quvvatlarni ishga tushirish | C24: 0.7 | D24: 0.75 | E24: 0.8 | F24: 0.85 | G24: 0.9 | H24: 0.95 | I24: 1
B25: ISHLAB CHIQARISH HAJMI
B26: 30707942190044 | C26: =$D15*C$24 -> 71555400 | D26: =$D15*D$24 -> 76666500 | E26: =$D15*E$24 -> 81777600 | F26: =$D15*F$24 -> 86888700 | G26: =$D15*G$24 -> 91999800 | H26: =$D15*H$24 -> 97110900 | I26: =$D15*I$24 -> 102222000
B27: =B16 -> Parrandachilik | C27: =$D$16*C24 -> 0 | D27: =$D$16*D24 -> 0 | E27: =$D$16*E24 -> 0 | F27: =$D$16*F24 -> 0 | G27: =$D$16*G24 -> 0 | H27: =$D$16*H24 -> 0 | I27: =$D$16*I24 -> 0
B28: Tovuq boqish | C28: =$D$17*C24 -> 0 | D28: =$D$17*D24 -> 0 | E28: =$D$17*E24 -> 0 | F28: =$D$17*F24 -> 0 | G28: =$D$17*G24 -> 0 | H28: =$D$17*H24 -> 0 | I28: =$D$17*I24 -> 0
B29: =B18 -> "Bobur Аkbarov" MCHJ | C29: =$D$18*C24 -> 0 | D29: =$D$18*D24 -> 0 | E29: =$D$18*E24 -> 0 | F29: =$D$18*F24 -> 0 | G29: =$D$18*G24 -> 0 | H29: =$D$18*H24 -> 0 | I29: =$D$18*I24 -> 0
B30: Masuliyati cheklangan jamiyat | C30: =$D$19*C24 -> 0 | D30: =$D$19*D24 -> 0 | E30: =$D$19*E24 -> 0 | F30: =$D$19*F24 -> 0 | G30: =$D$19*G24 -> 0 | H30: =$D$19*H24 -> 0 | I30: =$D$19*I24 -> 0
B31: =B20 -> 0 | C31: =$D$20*C24 -> 0 | D31: =$D$20*D24 -> 0 | E31: =$D$20*E24 -> 0 | F31: =$D$20*F24 -> 0 | G31: =$D$20*G24 -> 0 | H31: =$D$20*H24 -> 0 | I31: =$D$20*I24 -> 0
B32: Akbarov boburjon Sobirjon o'g'li
B33: ЗАПАСЫ НА КОНЕЦ ГОДА
B34: AD 3859855 | C34: =C26*G15 -> 0 | D34: =D26*$G$15 -> 0 | E34: =E26*$G$15 -> 0 | F34: =F26*$G$15 -> 0 | G34: =G26*$G$15 -> 0 | H34: =H26*$G$15 -> 0 | I34: =I26*$G$15 -> 0
B35: =#REF! -> #REF! | C35: =#REF!*#REF! -> #REF! | D35: =#REF!*$G$15 -> #REF! | E35: =#REF!*$G$15 -> #REF! | F35: =#REF!*$G$15 -> #REF! | G35: =#REF!*$G$15 -> #REF! | H35: =#REF!*$G$15 -> #REF! | I35: =#REF!*$G$15 -> #REF!
B36: 07.07.1994 | C36: =C27*$G16 -> 0 | D36: =D27*$G16 -> 0 | E36: =E27*$G16 -> 0 | F36: =F27*$G16 -> 0 | G36: =G27*$G16 -> 0 | H36: =H27*$G16 -> 0 | I36: =I27*$G16 -> 0
B37: =B28 -> Tovuq boqish | C37: =C28*$G17 -> 0 | D37: =D28*$G17 -> 0 | E37: =E28*$G17 -> 0 | F37: =F28*$G17 -> 0 | G37: =G28*$G17 -> 0 | H37: =H28*$G17 -> 0 | I37: =I28*$G17 -> 0
B38: 150000000 | C38: =C29*$G18 -> 0 | D38: =D29*$G18 -> 0 | E38: =E29*$G18 -> 0 | F38: =F29*$G18 -> 0 | G38: =G29*$G18 -> 0 | H38: =H29*$G18 -> 0 | I38: =I29*$G18 -> 0
B39: =B30 -> Masuliyati cheklangan jamiyat | C39: =C30*$G19 -> 0 | D39: =D30*$G19 -> 0 | E39: =E30*$G19 -> 0 | F39: =F30*$G19 -> 0 | G39: =G30*$G19 -> 0 | H39: =H30*$G19 -> 0 | I39: =I30*$G19 -> 0
B40: =B31 -> 0 | C40: =C31*$G20 -> 0 | D40: =D31*$G20 -> 0 | E40: =E31*$G20 -> 0 | F40: =F31*$G20 -> 0 | G40: =G31*$G20 -> 0 | H40: =H31*$G20 -> 0 | I40: =I31*$G20 -> 0
B42: 50000000
B43: =+B15 -> 0 | C43: =C24*$E$4 -> 71555400 | D43: =D24*$E$4 -> 76666500 | E43: =E24*$E$4 -> 81777600 | F43: =F24*$E$4 -> 86888700 | G43: =G24*$E$4 -> 91999800 | H43: =H24*$E$4 -> 97110900 | I43: =I24*$E$4 -> 102222000
B44: 100000000 | C44: =C27-C36 -> 0 | D44: =D27-D36 -> 0 | E44: =E27-E36 -> 0 | F44: =F27-F36 -> 0 | G44: =G27-G36 -> 0 | H44: =H27-H36 -> 0 | I44: =I27-I36 -> 0
B45: =B37 -> Tovuq boqish | C45: =C28-C37 -> 0 | D45: =D28-D37 -> 0 | E45: =E28-E37 -> 0 | F45: =F28-F37 -> 0 | G45: =G28-G37 -> 0 | H45: =H28-H37 -> 0 | I45: =I28-I37 -> 0
B46: 84 | C46: =C29-C38 -> 0 | D46: =D29-D38 -> 0 | E46: =E29-E38 -> 0 | F46: =F29-F38 -> 0 | G46: =G29-G38 -> 0 | H46: =H29-H38 -> 0 | I46: =I29-I38 -> 0
B47: =B39 -> Masuliyati cheklangan jamiyat | C47: =C30-C39 -> 0 | D47: =D30-D39 -> 0 | E47: =E30-E39 -> 0 | F47: =F30-F39 -> 0 | G47: =G30-G39 -> 0 | H47: =H30-H39 -> 0 | I47: =I30-I39 -> 0
B48: 24 | C48: =C31-C40 -> 0 | D48: =D31-D40 -> 0 | E48: =E31-E40 -> 0 | F48: =F31-F40 -> 0 | G48: =G31-G40 -> 0 | H48: =H31-H40 -> 0 | I48: =I31-I40 -> 0
B50: 14
B51: =B43 -> 0 | C51: =C43*$F15 -> 357777000000 | D51: =D43*$F15 -> 383332500000 | E51: =E43*$F15 -> 408888000000 | F51: =F43*$F15 -> 434443500000 | G51: =G43*$F15 -> 459999000000 | H51: =H43*$F15 -> 485554500000 | I51: =I43*$F15 -> 511110000000
B52: 1874001.2 | C52: =C44*$F16 -> 0 | D52: =D44*$F16 -> 0 | E52: =E44*$F16 -> 0 | F52: =F44*$F16 -> 0 | G52: =G44*$F16 -> 0 | H52: =H44*$F16 -> 0 | I52: =I44*$F16 -> 0
B53: 1.574161e+08 | C53: =C45*$F17 -> 0 | D53: =D45*$F17 -> 0 | E53: =E45*$F17 -> 0 | F53: =F45*$F17 -> 0 | G53: =G45*$F17 -> 0 | H53: =H45*$F17 -> 0 | I53: =I45*$F17 -> 0
B54: 57416097 | C54: =C46*$F18 -> 0 | D54: =D46*$F18 -> 0 | E54: =E46*$F18 -> 0 | F54: =F46*$F18 -> 0 | G54: =G46*$F18 -> 0 | H54: =H46*$F18 -> 0 | I54: =I46*$F18 -> 0
...

Sheet Loans
F1: 8-9-ILOVA
B2: TO'LOV GRAFIGI
C3: Kredit muddati | D3: =+ВВОД!B46 -> 84 | E3: oy
C5: Imtiyozli davr | D5: =+ВВОД!B48 -> 24 | E5: oy
C6: Foiz | D6: =+ВВОД!B50 -> 18 | E6: foiz
C7: Jamg'arma kompensatsiyasi | D7: 0 | E7: foiz
C9: Kredit summasi | D9: =+ВВОД!B44 -> 100000000 | E9: sum
B11: OYLAR | C11: ASOSIY QARZ TO'LOVI | D11: ASOSIY QARZ QOLDIG'I | E11: FOIZ TO'LOVLARI | F11: JAMI TO'LOV
B12: 1 | D12: =D9 -> 100000000 | E12: =(D9*$D$6)/12/100 -> 1500000 | F12: =C12+E12 -> 1500000 | G12: 1-йил
B13: 2 | D13: =D12-C12 -> 100000000 | E13: =(D9*$D$6)/12/100 -> 1500000 | F13: =C13+E13 -> 1500000 | G13: 1-йил
B14: 3 | D14: =D13-C13 -> 100000000 | E14: =(D9*$D$6)/12/100 -> 1500000 | F14: =C14+E14 -> 1500000 | G14: 1-йил
B15: 4 | D15: =D14-C14 -> 100000000 | E15: =(D12*$D$6)/12/100 -> 1500000 | F15: =C15+E15 -> 1500000 | G15: 1-йил
B16: 5 | D16: =D15-C15 -> 100000000 | E16: =(D13*$D$6)/12/100 -> 1500000 | F16: =C16+E16 -> 1500000 | G16: 1-йил
B17: 6 | D17: =D16-C16 -> 100000000 | E17: =(D14*$D$6)/12/100 -> 1500000 | F17: =C17+E17 -> 1500000 | G17: 1-йил
B18: 7 | D18: =D17-C17 -> 100000000 | E18: =(D15*$D$6)/12/100 -> 1500000 | F18: =C18+E18 -> 1500000 | G18: 1-йил
B19: 8 | D19: =D18-C18 -> 100000000 | E19: =(D16*$D$6)/12/100 -> 1500000 | F19: =C19+E19 -> 1500000 | G19: 1-йил
B20: 9 | D20: =D19-C19 -> 100000000 | E20: =(D17*$D$6)/12/100 -> 1500000 | F20: =C20+E20 -> 1500000 | G20: 1-йил
B21: 10 | D21: =D20-C20 -> 100000000 | E21: =(D18*$D$6)/12/100 -> 1500000 | F21: =C21+E21 -> 1500000 | G21: 1-йил
B22: 11 | D22: =D21-C21 -> 100000000 | E22: =(D19*$D$6)/12/100 -> 1500000 | F22: =C22+E22 -> 1500000 | G22: 1-йил
B23: 12 | D23: =D22-C22 -> 100000000 | E23: =(D20*$D$6)/12/100 -> 1500000 | F23: =C23+E23 -> 1500000 | G23: 1-йил
B24: 13 | D24: =D23-C23 -> 100000000 | E24: =(D21*$D$6)/12/100 -> 1500000 | F24: =C24+E24 -> 1500000 | G24: 2-йил
B25: 14 | D25: =D24-C24 -> 100000000 | E25: =(D22*$D$6)/12/100 -> 1500000 | F25: =C25+E25 -> 1500000 | G25: 2-йил
B26: 15 | D26: =D25-C25 -> 100000000 | E26: =(D23*$D$6)/12/100 -> 1500000 | F26: =C26+E26 -> 1500000 | G26: 2-йил
... B35: 24 | D35: =D34-C34 -> 100000000 | E35: =(D32*$D$6)/12/100 -> 1500000 | F35: =C35+E35 -> 1500000 | G35: 2-йил
B36: 25 | C36: =+D9/60 -> 1666666.7 | D36: =D35-C35 -> 100000000 | E36: =(D33*$D$6)/12/100 -> 1500000 | F36: =C36+E36 -> 3166666.7 | G36: 3-йил
B37: 26 | C37: =+D9/60 -> 1666666.7 | D37: =D36-C36 -> 98333333 | E37: =(D34*$D$6)/12/100 -> 1500000 | F37: =C37+E37 -> 3166666.7 | G37: 3-йил
B38: 27 | C38: =+D9/60 -> 1666666.7 | D38: =D37-C37 -> 96666667 | E38: =(D35*$D$6)/12/100 -> 1500000 | F38: =C38+E38 -> 3166666.7 | G38: 3-йил
B39: 28 | C39: =+D9/60 -> 1666666.7 | D39: =D38-C38 -> 95000000 | E39: =(D36*$D$6)/12/100 -> 1500000 | F39: =C39+E39 -> 3166666.7 | G39: 3-йил
B40: 29 | C40: =+D9/60 -> 1666666.7 | D40: =D39-C39 -> 93333333 | E40: =(D37*$D$6)/12/100 -> 1475000 | F40: =C40+E40 -> 3141666.7 | G40: 3-йил
B41: 30 | C41: =+D9/60 -> 1666666.7 | D41: =D40-C40 -> 91666667 | E41: =(D38*$D$6)/12/100 -> 1450000 | F41: =C41+E41 -> 3116666.7 | G41: 3-йил
B42: 31 | C42: =+D9/60 -> 1666666.7 | D42: =D41-C41 -> 90000000 | E42: =(D39*$D$6)/12/100 -> 1425000 | F42: =C42+E42 -> 3091666.7 | G42: 3-йил
B43: 32 | C43: =+D9/60 -> 1666666.7 | D43: =D42-C42 -> 88333333 | E43: =(D40*$D$6)/12/100 -> 1400000 | F43: =C43+E43 -> 3066666.7 | G43: 3-йил
B44: 33 | C44: =+D9/60 -> 1666666.7 | D44: =D43-C43 -> 86666667 | E44: =(D41*$D$6)/12/100 -> 1375000 | F44: =C44+E44 -> 3041666.7 | G44: 3-йил
B45: 34 | C45: =+D9/60 -> 1666666.7 | D45: =D44-C44 -> 85000000 | E45: =(D42*$D$6)/12/100 -> 1350000 | F45: =C45+E45 -> 3016666.7 | G45: 3-йил
B46: 35 | C46: =+D9/60 -> 1666666.7 | D46: =D45-C45 -> 83333333 | E46: =(D43*$D$6)/12/100 -> 1325000 | F46: =C46+E46 -> 2991666.7 | G46: 3-йил
B47: 36 | C47: =+D9/60 -> 1666666.7 | D47: =D46-C46 -> 81666667 | E47: =(D44*$D$6)/12/100 -> 1300000 | F47: =C47+E47 -> 2966666.7 | G47: 3-йил
B48: 37 | C48: =+D9/60 -> 1666666.7 | D48: =D47-C47 -> 80000000 | E48: =(D45*$D$6)/12/100 -> 1275000 | F48: =C48+E48 -> 2941666.7 | G48: 4-йил
B49: 38 | C49: =+D9/60 -> 1666666.7 | D49: =D48-C48 -> 78333333 | E49: =(D46*$D$6)/12/100 -> 1250000 | F49: =C49+E49 -> 2916666.7 | G49: 4-йил
B50: 39 | C50: =+D9/60 -> 1666666.7 | D50: =D49-C49 -> 76666667 | E50: =(D47*$D$6)/12/100 -> 1225000 | F50: =C50+E50 -> 2891666.7 | G50: 4-йил
B51: 40 | C51: =+D9/60 -> 1666666.7 | D51: =D50-C50 -> 75000000 | E51: =(D48*$D$6)/12/100 -> 1200000 | F51: =C51+E51 -> 2866666.7 | G51: 4-йил
...

Sheet Taxes
G1: 7-ILOVA
B2: SOLIQ VA BOJLAR
B3: Soliqlar va chegirmalar turlari | C3: Soliq stavkasi | D3: Soliq solish obyekti | E3: =Depreciate!E4 -> 1-yil | F3: =Depreciate!F4 -> 2-yil | G3: =Depreciate!G4 -> 3-yil | H3: =Depreciate!H4 -> 4-yil | I3: =ProdPlan!G23 -> 5-yil | J3: =ProdPlan!H23 -> 6-yil | K3: =ProdPlan!I23 -> 7-yil
B4: Налог на имущество | C4: 0.035 | D4: от среднегодовой стоимости имущества | E4: 0 | F4: 0 | G4: 0 | H4: 0 | I4: 0 | J4: 0 | K4: 0
B6: Земельный налог | D6: исходя из занимаемой площади | E6: х | F6: 0 | G6: 0 | H6: 0 | I6: 0 | J6: 0 | K6: 0
B7: Налог на недра
B8: Налоги включаемые в себестоимость | E8: =SUM(E4:E7) -> 0 | F8: =SUM(F4:F7) -> 0 | G8: =SUM(G4:G7) -> 0 | H8: =SUM(H4:H7) -> 0 | I8: =SUM(I4:I7) -> 0 | J8: =SUM(J4:J7) -> 0 | K8: =SUM(K4:K7) -> 0
B9: Отчисления в ЕДФ | C9: 0.01 | D9: от объема реализации
B10: Отчисления в пенс. Фонд | C10: 0.007 | D10: от объема реализации
B11: Экологический налог | C11: 0.01 | D11: от себестоимости | E11: 0 | F11: 0 | G11: 0
B12: Налоги и сборы вкл. в расходы периода
B13: Yagona soliq to'lovi | C13: 0.04 | D13: sotishdan tushgan daromad | E13: =4%*ProfLoss!C6 -> 14311080000 | F13: =4%*ProfLoss!D6 -> 15333300000 | G13: =4%*ProfLoss!E6 -> 16355520000 | H13: =4%*ProfLoss!F6 -> 17377740000 | I13: =4%*ProfLoss!G6 -> 18399960000 | J13: =4%*ProfLoss!H6 -> 19422180000 | K13: =4%*ProfLoss!I6 -> 20444400000
B14: Акцизный налог | C14: х | D14: от выручки | E14: 0 | F14: 0 | G14: 0 | H14: 0 | I14: 0 | J14: 0 | K14: 0
B15: НДС | C15: 0.2 | D15: от выручки | E15: 0 | F15: 0 | G15: 0 | H15: 0 | I15: 0 | J15: 0 | K15: 0
B16: Другие местные налоги и сборы | C16: 0.08 | D16: от прибыли | E16: 0 | F16: 0 | G16: 0 | H16: 0 | I16: 0 | J16: 0 | K16: 0
B17: JAMIY SOLIQ VA BOJLARI | E17: =E8+E13 -> 14311080000 | F17: =F8+F13 -> 15333300000 | G17: =G8+G13 -> 16355520000 | H17: =H8+H13 -> 17377740000 | I17: =I8+I13 -> 18399960000 | J17: =J8+J13 -> 19422180000 | K17: =K8+K13 -> 20444400000

Sheet Loans 2
F1: ПРИЛОЖЕНИЕ 9
B2: ВЫПЛАТЫ ПО ДОЛГОСРОЧНОМУ КРЕДИТУ
C3: Срок кредита | D3: 7 лет
C4: Инвестиционный период | D4: 0 месяц
C5: Льготный период | D5: 24 месяц
C6: Процентная ставка | D6: 0.055
C7: Периодичность выплат | D7: ежемесячно
C8: сумма кредита (евро) | D8: ='Share of Costs'!F6 -> 100000000
B10: ПЕРИОДЫ ВЫПЛАТ | C10: ПОГАШЕНИЕ ОСНОВНОГО ДОЛГА | D10: ОСТАТОК ССУДНОЙ ЗАДОЛЖЕННОСТИ | E10: ВЫПЛАТЫ ПРОЦЕНТОВ | F10: ВСЕГО ВЫПЛАТ
B11: 1 мес | C11: 0 | D11: =D8 -> 100000000 | E11: 0 | F11: =C11+E11 -> 0 | G11: 1год
B12: 2 мес | C12: 0 | D12: =+D11-C11 -> 100000000 | E12: 0 | F12: =C12+E12 -> 0 | G12: 1год
B13: 3 мес | C13: 0 | D13: =+D12-C12 -> 100000000 | E13: 0 | F13: =C13+E13 -> 0 | G13: 1год
B14: 4 мес | C14: 0 | D14: =+D13-C13 -> 100000000 | E14: 0 | F14: =C14+E14 -> 0 | G14: 1год
B15: 5 мес | C15: 0 | D15: =+D14-C14 -> 100000000 | E15: 0 | F15: =C15+E15 -> 0 | G15: 1год
B16: 6 мес | C16: 0 | D16: =+D15-C15 -> 100000000 | E16: =(D16*$D$6/2) -> 2750000 | F16: =C16+E16 -> 2750000 | G16: 1год
B17: 7 мес | C17: 0 | D17: =+D16-C16 -> 100000000 | E17: 0 | F17: =C17+E17 -> 0 | G17: 1год
B18: 8 мес | C18: 0 | D18: =+D17-C17 -> 100000000 | E18: 0 | F18: =C18+E18 -> 0 | G18: 1год
B19: 9 мес | C19: 0 | D19: =+D18-C18 -> 100000000 | E19: 0 | F19: =C19+E19 -> 0 | G19: 1год
B20: 10 мес | C20: 0 | D20: =+D19-C19 -> 100000000 | E20: 0 | F20: =C20+E20 -> 0 | G20: 1год
B21: 11 мес | C21: =C20 -> 0 | D21: =+D20-C20 -> 100000000 | E21: 0 | F21: =C21+E21 -> 0 | G21: 1год
B22: 12 мес | C22: =C21 -> 0 | D22: =+D21-C21 -> 100000000 | E22: =(D22*$D$6/2) -> 2750000 | F22: =C22+E22 -> 2750000 | G22: 1год
B23: 13 мес | C23: =C22 -> 0 | D23: =+D22-C22 -> 100000000 | E23: 0 | F23: =C23+E23 -> 0 | G23: 2год
B24: 14 мес | C24: =C23 -> 0 | D24: =+D23-C23 -> 100000000 | E24: 0 | F24: =C24+E24 -> 0 | G24: 2год
B25: 15 мес | C25: =C24 -> 0 | D25: =+D24-C24 -> 100000000 | E25: 0 | F25: =C25+E25 -> 0 | G25: 2год
B26: 16 мес | C26: =C25 -> 0 | D26: =+D25-C25 -> 100000000 | E26: 0 | F26: =C26+E26 -> 0 | G26: 2год
B27: 17 мес | C27: =C26 -> 0 | D27: =+D26-C26 -> 100000000 | E27: 0 | F27: =C27+E27 -> 0 | G27: 2год
B28: 18 мес | C28: =C27 -> 0 | D28: =+D27-C27 -> 100000000 | E28: =(D28*$D$6/2) -> 2750000 | F28: =C28+E28 -> 2750000 | G28: 2год
B29: 19 мес | C29: =C28 -> 0 | D29: =+D28-C28 -> 100000000 | E29: 0 | F29: =C29+E29 -> 0 | G29: 2год
B30: 20 мес | C30: =C29 -> 0 | D30: =+D29-C29 -> 100000000 | E30: 0 | F30: =C30+E30 -> 0 | G30: 2год
B31: 21 мес | C31: =C30 -> 0 | D31: =+D30-C30 -> 100000000 | E31: 0 | F31: =C31+E31 -> 0 | G31: 2год
B32: 22 мес | C32: =C31 -> 0 | D32: =+D31-C31 -> 100000000 | E32: 0 | F32: =C32+E32 -> 0 | G32: 2год
B33: 23 мес | C33: =C32 -> 0 | D33: =+D32-C32 -> 100000000 | E33: 0 | F33: =C33+E33 -> 0 | G33: 2год
B34: 24 мес | C34: =D8/11 -> 9090909.1 | D34: =+D33-C33 -> 100000000 | E34: =(D34*$D$6/2) -> 2750000 | F34: =C34+E34 -> 11840909 | G34: 2год
B35: 25 мес | C35: 0 | D35: =+D34-C34 -> 90909091 | E35: 0 | F35: =C35+E35 -> 0 | G35: 3год
B36: 26 мес | C36: =C35 -> 0 | D36: =+D35-C35 -> 90909091 | E36: 0 | F36: =C36+E36 -> 0 | G36: 3год
B37: 27 мес | C37: =C36 -> 0 | D37: =+D36-C36 -> 90909091 | E37: 0 | F37: =C37+E37 -> 0 | G37: 3год
B38: 28 мес | C38: =C37 -> 0 | D38: =+D37-C37 -> 90909091 | E38: 0 | F38: =C38+E38 -> 0 | G38: 3год
B39: 29 мес | C39: =C38 -> 0 | D39: =+D38-C38 -> 90909091 | E39: 0 | F39: =C39+E39 -> 0 | G39: 3год
B40: 30 мес | C40: =C34 -> 9090909.1 | D40: =+D39-C39 -> 90909091 | E40: =(D40*$D$6/2) -> 2500000 | F40: =C40+E40 -> 11590909 | G40: 3год
B41: 31 мес | C41: 0 | D41: =+D40-C40 -> 81818182 | E41: 0 | F41: =C41+E41 -> 0 | G41: 3год
...

Sheet CostTotal
B2: TO'LIQ QUVVATLI BO'LGAN ISHLAB CHIQARISH XARAJATLARI | F2: 10-ILOVA | I2: Допущения использованные в расчетах
B3: XARAJATLAR | C3: TO'LIQ XARAJATLAR | D3: DOIMIY XARAJATLAR | F3: O'ZGARUVChAN XARAJATLAR | I3: Статьи расходов | J3: Примечания | K3: сумма в сум
D4: сумма | E4: % | F4: сумма | G4: % | I4: Расходы на рекламу | J4: 11200 тыс. сум в году, взята с предоставленного допольнения | K4: 80000
B5: To'g'ridan-to'g'ri xarajatlar | C5: =ProdPlan!G4*1% -> 5111100000 | D5: =C5*E5 -> 4088880000 | E5: 0.8 | F5: =+C5*G5 -> 1.02222e+09 | G5: =1-E5 -> 0.2 | I5: Торговые издержки | J5: Расходы на упаковку, невозврат. Тара и доставку, взят с доп. | K5: 80000
B7: Operatsion xarajatlar | C7: =Labour!F33 -> 253000 | D7: =C7*E7 -> 177100 | E7: 0.7 | F7: =+C7*G7 -> 75900 | G7: =1-E7 -> 0.3 | I7: Инженерные коммуникации | J7: Прокладка, обсл. И прозвонка действующих инж. Комм. | K7: 2040
B8: Jami amortizatsiya | C8: =Depreciate!E7 -> 21714286 | D8: =C8*E8 -> 21714286 | E8: 1 | F8: =+C8*G8 -> 0 | G8: =1-E8 -> 0 | I8: Офисные расходы | J8: На покупку канц. Товаров и представительские расходы | K8: 10000
B9: Ishlab chiqarish xodimlarining ish haqi | C9: =Labour!F18+Labour!F13 -> 108000000 | D9: =C9*E9 -> 0 | E9: 0 | F9: =+C9*G9 -> 108000000 | G9: =1-E9 -> 1
B10: Ijtimoiy soliq | C10: =Labour!F19+Labour!F14 -> 12960000 | D10: =C10*E10 -> 0 | E10: 0 | F10: =+C10*G10 -> 12960000 | G10: =1-E10 -> 1 | I10: Транспортные расходы | J10: Расходы на ж/д транспорт | K10: 31360
B11: Ma'muriyat xodimlari ish haqi | C11: =Labour!F7 -> 14400000 | D11: =C11*E11 -> 14400000 | E11: 1 | F11: =+C11*G11 -> 0 | G11: =1-E11 -> 0 | I11: ГСМ | J11: На диз. Топливо 17 000 литров и автомобильных масел | K11: 7500
B12: =B10 -> Ijtimoiy soliq | C12: =Labour!F8 -> 1728000 | D12: =C12*E12 -> 1728000 | E12: 1 | F12: =+C12*G12 -> 0 | G12: =1-E12 -> 0 | I12: Юридические и финансовые расходы | J12: На оплату банковских и юридических услуг | K12: 6000
B13: Boshqa ma'muriy xarajatlar | C13: =F18*0.2% -> 1022220000 | D13: =C13*E13 -> 511110000 | E13: 0.5 | F13: =+C13*G13 -> 511110000 | G13: =1-E13 -> 0.5
B14: Asosiy vositalarga texnik xizmat ko'rsatish va joriy ta'mirlash | C14: =C8*1% -> 217142.86 | D14: =C14*E14 -> 152000 | E14: 0.7 | F14: =+C14*G14 -> 65142.857 | G14: =1-E14 -> 0.3
B15: Marketing xarajatlari (0,2%) | C15: =F18*0.2% -> 1022220000 | D15: =C15*E15 -> 715554000 | E15: 0.7 | F15: =+C15*G15 -> 3.06666e+08 | G15: =1-E15 -> 0.3
B16: Boshqa ko'zda tutilmagan xarajatlar | C16: =F18*0.2% -> 1022220000 | D16: =C16*E16 -> 511110000 | E16: 0.5 | F16: =+C16*G16 -> 511110000 | G16: =1-E16 -> 0.5
B17: JAMI XARAJATLAR | C17: =SUM(C5:C16) -> 8.3370324e+09 | D17: =SUM(D5:D16) -> 5.8648254e+09 | E17: =D17/C17 -> 0.70346678 | F17: =SUM(F5:F16) -> 2.472207e+09 | G17: =F17/C17 -> 0.29653322
B18: TO'LIQ QUVVATDA SOTISH | F18: =ProdPlan!D15*ProdPlan!F15+ProdPlan!D16*ProdPlan!F16+ProdPlan!D17*ProdPlan!F17+ProdPlan!D18*ProdPlan!F18+ProdPlan!D19*ProdPlan!F19+ProdPlan!D20*ProdPlan!F20 -> 511110000000 | I18: Итого прочие расходы | K18: =SUM(K4:K15) -> 216900
B19: ZARARSIZLANISH NUQTASI | F19: =D17/(F18-F17) -> 0.011530455

Sheet CostSold
B2: TO'LIQ YILLIK XARAJATLAR | G2: 11-ILOVA
B3: Xarajat moddalari | C3: =ProdPlan!C23 -> 1-yil | D3: =ProdPlan!D23 -> 2-yil | E3: =ProdPlan!E23 -> 3-yil | F3: =ProdPlan!F23 -> 4-yil | G3: =ProdPlan!G23 -> 5-yil | H3: =ProdPlan!H23 -> 6-yil | I3: =ProdPlan!I23 -> 7-yil
B4: Rivojlanish quvvati | C4: =ProdPlan!C24 -> 0.7 | D4: =ProdPlan!D24 -> 0.75 | E4: =ProdPlan!E24 -> 0.8 | F4: =ProdPlan!F24 -> 0.85 | G4: =ProdPlan!G24 -> 0.9 | H4: =ProdPlan!H24 -> 0.95 | I4: =ProdPlan!I24 -> 1
B5: =CostTotal!B5 -> To'g'ridan-to'g'ri xarajatlar | C5: =CostTotal!$D$5+CostTotal!$F$5*C4 -> 4804434000 | D5: =CostTotal!$D$5+CostTotal!$F$5*D4 -> 4855545000 | E5: =CostTotal!$D$5+CostTotal!$F$5*E4 -> 4906656000 | F5: =CostTotal!$D$5+CostTotal!$F$5*F4 -> 4957767000 | G5: =CostTotal!$D$5+CostTotal!$F$5*G4 -> 5008878000 | H5: =CostTotal!$D$5+CostTotal!$F$5*H4 -> 5059989000 | I5: =CostTotal!$D$5+CostTotal!$F$5*I4 -> 5111100000
B6: =+CostTotal!B9 -> Ishlab chiqarish xodimlarining ish haqi | C6: =CostTotal!$D$9+CostTotal!$F$9*CostSold!C4 -> 75600000 | D6: =CostTotal!$D$9+CostTotal!$F$9*CostSold!D4 -> 81000000 | E6: =CostTotal!$D$9+CostTotal!$F$9*CostSold!E4 -> 86400000 | F6: =CostTotal!$D$9+CostTotal!$F$9*CostSold!F4 -> 91800000 | G6: =CostTotal!$D$9+CostTotal!$F$9*CostSold!G4 -> 97200000 | H6: =CostTotal!$D$9+CostTotal!$F$9*CostSold!H4 -> 102600000 | I6: =CostTotal!$D$9+CostTotal!$F$9*CostSold!I4 -> 108000000
B7: =+CostTotal!B10 -> Ijtimoiy soliq | C7: =CostTotal!$D$10+CostTotal!$F$10*CostSold!C4 -> 9072000 | D7: =(CostTotal!$D$10+CostTotal!$F$10*CostSold!D4) -> 9720000 | E7: =(CostTotal!$D$10+CostTotal!$F$10*CostSold!E4) -> 10368000 | F7: =(CostTotal!$D$10+CostTotal!$F$10*CostSold!F4) -> 11016000 | G7: =(CostTotal!$D$10+CostTotal!$F$10*CostSold!G4) -> 11664000 | H7: =(CostTotal!$D$10+CostTotal!$F$10*CostSold!H4) -> 12312000 | I7: =(CostTotal!$D$10+CostTotal!$F$10*CostSold!I4) -> 12960000
B8: =CostTotal!B7 -> Operatsion xarajatlar | C8: =CostTotal!$D$7+CostTotal!$F$7*CostSold!C4 -> 230230 | D8: =CostTotal!$D$7+CostTotal!$F$7*CostSold!D4 -> 234025 | E8: =CostTotal!$D$7+CostTotal!$F$7*CostSold!E4 -> 237820 | F8: =CostTotal!$D$7+CostTotal!$F$7*CostSold!F4 -> 241615 | G8: =CostTotal!$D$7+CostTotal!$F$7*CostSold!G4 -> 245410 | H8: =CostTotal!$D$7+CostTotal!$F$7*CostSold!H4 -> 249205 | I8: =CostTotal!$D$7+CostTotal!$F$7*CostSold!I4 -> 253000
B9: Amortizatsiya | C9: =Depreciate!E7 -> 21714286 | D9: =Depreciate!F7 -> 21714286 | E9: =Depreciate!G7 -> 21714286 | F9: =Depreciate!H7 -> 21714286 | G9: =Depreciate!I7 -> 21714286 | H9: =Depreciate!J7 -> 21714286 | I9: =Depreciate!K7 -> 21714286
B10: TANNARX | C10: =+C9+C8+C7+C6+C5 -> 4.9110505e+09 | D10: =+D9+D8+D7+D6+D5 -> 4.9682133e+09 | E10: =+E9+E8+E7+E6+E5 -> 5.0253761e+09 | F10: =+F9+F8+F7+F6+F5 -> 5.0825389e+09 | G10: =+G9+G8+G7+G6+G5 -> 5.1397017e+09 | H10: =+H9+H8+H7+H6+H5 -> 5.1968645e+09 | I10: =+I9+I8+I7+I6+I5 -> 5.2540273e+09
B11: =CostTotal!B11 -> Ma'muriyat xodimlari ish haqi | C11: =+CostTotal!$D$11+CostTotal!$F$11*CostSold!C4 -> 14400000 | D11: =+CostTotal!$D$11+CostTotal!$F$11*CostSold!D4 -> 14400000 | E11: =+CostTotal!$D$11+CostTotal!$F$11*CostSold!E4 -> 14400000 | F11: =+CostTotal!$D$11+CostTotal!$F$11*CostSold!F4 -> 14400000 | G11: =+CostTotal!$D$11+CostTotal!$F$11*CostSold!G4 -> 14400000 | H11: =+CostTotal!$D$11+CostTotal!$F$11*CostSold!H4 -> 14400000 | I11: =+CostTotal!$D$11+CostTotal!$F$11*CostSold!I4 -> 14400000
B12: =+B7 -> Ijtimoiy soliq | C12: =+CostTotal!$D$12+CostTotal!$F$12*CostSold!C4 -> 1728000 | D12: =+CostTotal!$D$12+CostTotal!$F$12*CostSold!D4 -> 1728000 | E12: =+CostTotal!$D$12+CostTotal!$F$12*CostSold!E4 -> 1728000 | F12: =+CostTotal!$D$12+CostTotal!$F$12*CostSold!F4 -> 1728000 | G12: =+CostTotal!$D$12+CostTotal!$F$12*CostSold!G4 -> 1728000 | H12: =+CostTotal!$D$12+CostTotal!$F$12*CostSold!H4 -> 1728000 | I12: =+CostTotal!$D$12+CostTotal!$F$12*CostSold!I4 -> 1728000
B13: =CostTotal!B16 -> Boshqa ko'zda tutilmagan xarajatlar | C13: =CostTotal!$D$16+CostTotal!$F$16*C4 -> 868887000 | D13: =CostTotal!$D$16+CostTotal!$F$16*D4 -> 894442500 | E13: =CostTotal!$D$16+CostTotal!$F$16*E4 -> 919998000 | F13: =CostTotal!$D$16+CostTotal!$F$16*F4 -> 945553500 | G13: =CostTotal!$D$16+CostTotal!$F$16*G4 -> 971109000 | H13: =CostTotal!$D$16+CostTotal!$F$16*H4 -> 996664500 | I13: =CostTotal!$D$16+CostTotal!$F$16*I4 -> 1022220000
B14: =CostTotal!B14 -> Asosiy vositalarga texnik xizmat ko'rsatish va joriy ta'mirlash | C14: =CostTotal!$D$14+CostTotal!$F$14*C4 -> 197600 | D14: =CostTotal!$D$14+CostTotal!$F$14*D4 -> 200857.14 | E14: =CostTotal!$D$14+CostTotal!$F$14*E4 -> 204114.29 | F14: =CostTotal!$D$14+CostTotal!$F$14*F4 -> 207371.43 | G14: =CostTotal!$D$14+CostTotal!$F$14*G4 -> 210628.57 | H14: =CostTotal!$D$14+CostTotal!$F$14*H4 -> 213885.71 | I14: =CostTotal!$D$14+CostTotal!$F$14*I4 -> 217142.86
B15: Marketing xarajatlar | C15: =CostTotal!$D$15+CostTotal!$F$15*C4 -> 930220200 | D15: =CostTotal!$D$15+CostTotal!$F$15*D4 -> 945553500 | E15: =CostTotal!$D$15+CostTotal!$F$15*E4 -> 960886800 | F15: =CostTotal!$D$15+CostTotal!$F$15*F4 -> 976220100 | G15: =CostTotal!$D$15+CostTotal!$F$15*G4 -> 991553400 | H15: =CostTotal!$D$15+CostTotal!$F$15*H4 -> 1006886700 | I15: =CostTotal!$D$15+CostTotal!$F$15*I4 -> 1022220000
B16: =CostTotal!B13 -> Boshqa ma'muriy xarajatlar | C16: =CostTotal!$D$13+CostTotal!$F$13*C4 -> 868887000 | D16: =CostTotal!$D$13+CostTotal!$F$13*D4 -> 894442500 | E16: =CostTotal!$D$13+CostTotal!$F$13*E4 -> 919998000 | F16: =CostTotal!$D$13+CostTotal!$F$13*F4 -> 945553500 | G16: =CostTotal!$D$13+CostTotal!$F$13*G4 -> 971109000 | H16: =CostTotal!$D$13+CostTotal!$F$13*H4 -> 996664500 | I16: =CostTotal!$D$13+CostTotal!$F$13*I4 -> 1022220000
B17: Davr xarajatlari | C17: =SUM(C11:C16) -> 2684319800 | D17: =SUM(D11:D16) -> 2.7507674e+09 | E17: =SUM(E11:E16) -> 2.8172149e+09 | F17: =SUM(F11:F16) -> 2.8836625e+09 | G17: =SUM(G11:G16) -> 2.95011e+09 | H17: =SUM(H11:H16) -> 3.0165576e+09 | I17: =SUM(I11:I16) -> 3.0830051e+09
B18: Operatsion xarajatlar | C18: =+C10+C17 -> 7.5953703e+09 | D18: =+D10+D17 -> 7.7189807e+09 | E18: =+E10+E17 -> 7842591020 | F18: =+F10+F17 -> 7.9662014e+09 | G18: =+G10+G17 -> 8.0898117e+09 | H18: =+H10+H17 -> 8.2134221e+09 | I18: =+I10+I17 -> 8.3370324e+09
B19: Kredit foizlari | C19: =SUM(Loans!E12:E23) -> 18000000 | D19: =SUM(Loans!E24:E35) -> 18000000 | E19: =SUM(Loans!E36:E47) -> 17100000 | F19: =SUM(Loans!E48:E59) -> 13650000 | G19: =SUM(Loans!E60:E72) -> 10725000 | H19: =SUM(Loans!E72:E83) -> 6450000 | I19: =SUM(Loans!E84:E95) -> 2850000
B20: Jami moliyaviy xarajatlar | C20: =SUM(C19:C19) -> 18000000 | D20: =SUM(Loans!E24:E35) -> 18000000 | E20: =SUM(E19) -> 17100000 | F20: =SUM(F19) -> 13650000 | G20: =SUM(G19) -> 10725000 | H20: =SUM(Loans!E72:E83) -> 6450000 | I20: =SUM(Loans!E84:E95) -> 2850000
B21: SOTILGAN MAHSULOTLARNING XARAJATLARI | C21: =C18+C20 -> 7.6133703e+09 | D21: =D18+D20 -> 7.7369807e+09 | E21: =E18+E20 -> 7859691020 | F21: =F18+F20 -> 7.9798514e+09 | G21: =G18+G20 -> 8.1005367e+09 | H21: =H18+H20 -> 8.2198721e+09 | I21: =I18+I20 -> 8.3398824e+09

Sheet ProfLoss
B2: KUTILAYOTGAN FOYDA VA ZARAR | G2: 12-ILOVA
B3: Ko'rsatgichlar | C3: =ProdPlan!C23 -> 1-yil | D3: =ProdPlan!D23 -> 2-yil | E3: =ProdPlan!E23 -> 3-yil | F3: =ProdPlan!F23 -> 4-yil | G3: =+ProdPlan!G23 -> 5-yil | H3: =+ProdPlan!H23 -> 6-yil | I3: =ProdPlan!I23 -> 7-yil
B4: Sotishdan tushgan daromad | C4: =ProdPlan!C58 -> 357777000000 | D4: =ProdPlan!D58 -> 383332500000 | E4: =ProdPlan!E58 -> 408888000000 | F4: =ProdPlan!F58 -> 434443500000 | G4: =+ProdPlan!G58 -> 459999000000 | H4: =+ProdPlan!H58 -> 485554500000 | I4: =+ProdPlan!I58 -> 511110000000
B5: Налог на потребление ГСМ | C5: =Taxes!E5 -> 0 | D5: =Taxes!F5 -> 0 | E5: =Taxes!G5 -> 0 | F5: =Taxes!H5 -> 0
B6: Sof sotishdan tushgan daromad | C6: =ProdPlan!C58-C5 -> 357777000000 | D6: =ProdPlan!D58-D5 -> 383332500000 | E6: =ProdPlan!E58-E5 -> 408888000000 | F6: =ProdPlan!F58-F5 -> 434443500000 | G6: =ProdPlan!G58-G5 -> 459999000000 | H6: =ProdPlan!H58-H5 -> 485554500000 | I6: =ProdPlan!I58-I5 -> 511110000000
B7: xizmatlar | C7: =+CostSold!C10 -> 4.9110505e+09 | D7: =+CostSold!D10 -> 4.9682133e+09 | E7: =+CostSold!E10 -> 5.0253761e+09 | F7: =+CostSold!F10 -> 5.0825389e+09 | G7: =+CostSold!G10 -> 5.1397017e+09 | H7: =+CostSold!H10 -> 5.1968645e+09 | I7: =+CostSold!I10 -> 5.2540273e+09
B8: Umumiy daromad | C8: =C6-C7 -> 3.5286595e+11 | D8: =D6-D7 -> 3.7836429e+11 | E8: =E6-E7 -> 4.0386262e+11 | F8: =F6-F7 -> 4.2936096e+11 | G8: =G6-G7 -> 4.548593e+11 | H8: =H6-H7 -> 4.8035764e+11 | I8: =I6-I7 -> 5.0585597e+11
B9: Ma'muriy xarajatlar | C9: =CostSold!C11+CostSold!C12 -> 16128000 | D9: =CostSold!D11+CostSold!D12 -> 16128000 | E9: =CostSold!E11+CostSold!E12 -> 16128000 | F9: =CostSold!F11+CostSold!F12 -> 16128000 | G9: =CostSold!G11+CostSold!G12 -> 16128000 | H9: =CostSold!H11+CostSold!H12 -> 16128000 | I9: =CostSold!I11+CostSold!I12 -> 16128000
B10: Marketing xarajatlar | C10: =CostSold!C15 -> 930220200 | D10: =CostSold!D15 -> 945553500 | E10: =CostSold!E15 -> 960886800 | F10: =CostSold!F15 -> 976220100 | G10: =CostSold!G15 -> 991553400 | H10: =CostSold!H15 -> 1006886700 | I10: =CostSold!I15 -> 1022220000
B11: Boshqa xarajatlar | C11: =+CostSold!C13+CostSold!C14+CostSold!C16 -> 1737971600 | D11: =+CostSold!D13+CostSold!D14+CostSold!D16 -> 1.7890859e+09 | E11: =+CostSold!E13+CostSold!E14+CostSold!E16 -> 1.8402001e+09 | F11: =+CostSold!F13+CostSold!F14+CostSold!F16 -> 1.8913144e+09 | G11: =+CostSold!G13+CostSold!G14+CostSold!G16 -> 1.9424286e+09 | H11: =+CostSold!H13+CostSold!H14+CostSold!H16 -> 1.9935429e+09 | I11: =+CostSold!I13+CostSold!I14+CostSold!I16 -> 2.0446571e+09
B12: Operatsion foyda | C12: =C8-C9-C10-C11 -> 3.5018163e+11 | D12: =D8-D9-D10-D11 -> 3.7561352e+11 | E12: =E8-E9-E10-E11 -> 401045408980 | F12: =F8-F9-F10-F11 -> 4.264773e+11 | G12: =G8-G9-G10-G11 -> 4.5190919e+11 | H12: =H8-H9-H10-H11 -> 4.7734108e+11 | I12: =I8-I9-I10-I11 -> 5.0277297e+11
B13: Moliyaviy xarajatlar | C13: =CostSold!C20 -> 18000000 | D13: =CostSold!D20 -> 18000000 | E13: =CostSold!E20 -> 17100000 | F13: =CostSold!F20 -> 13650000 | G13: =CostSold!G20 -> 10725000 | H13: =CostSold!H20 -> 6450000 | I13: =CostSold!I20 -> 2850000
B14: Soliq to'laguncha foyda | C14: =C12-C13 -> 3.5016363e+11 | D14: =D12-D13 -> 3.7559552e+11 | E14: =E12-E13 -> 401028308980 | F14: =F12-F13 -> 4.2646365e+11 | G14: =G12-G13 -> 4.5189846e+11 | H14: =H12-H13 -> 4.7733463e+11 | I14: =I12-I13 -> 5.0277012e+11
B15: soliqlar | C15: =Taxes!E13 -> 14311080000 | D15: =Taxes!F13 -> 15333300000 | E15: =Taxes!G13 -> 16355520000 | F15: =Taxes!H13 -> 17377740000 | G15: =Taxes!I13 -> 18399960000 | H15: =Taxes!J13 -> 19422180000 | I15: =Taxes!K13 -> 20444400000
B16: Прочие налоги и отчисления | C16: =Taxes!E16 -> 0 | D16: =Taxes!F16 -> 0 | E16: =Taxes!G16 -> 0 | F16: =Taxes!H16 -> 0
B17: Sof daromad | C17: =C14-C15-C16 -> 3.3585255e+11 | D17: =D14-D15-D16 -> 3.6026222e+11 | E17: =E14-E15-E16 -> 384672788980 | F17: =F14-F15-F16 -> 4.0908591e+11 | G17: =G14-G15-G16 -> 4.334985e+11 | H17: =H14-H15-H16 -> 4.5791245e+11 | I17: =I14-I15-I16 -> 4.8232572e+11
B18: Rentabillik ko'rsatgichlari
B19: Sof rentabillik | C19: =C17/C6 -> 0.93872035 | D19: =D17/D6 -> 0.93981653 | E19: =E17/E6 -> 0.94077789 | F19: =F17/F6 -> 0.94163202 | G19: =G17/G6 -> 0.9423901 | H19: =H17/H6 -> 0.94307116 | I19: =I17/I6 -> 0.9436828
B20: Yalpi rentabillik | C20: =C8/C6 -> 0.98627343 | D20: =D8/D6 -> 0.98703942 | E20: =E8/E6 -> 0.98770965 | F20: =F8/F6 -> 0.98830104 | G20: =G8/G6 -> 0.98882671 | H20: =H8/H6 -> 0.98929705 | I20: =I8/I6 -> 0.98972036

Sheet CashFlow
B2: PUL OQIMI | H2: 13-ILOVA
B3: Ko'rsatgichlar | C3: 0 год | D3: =ProdPlan!C23 -> 1-yil | E3: =ProdPlan!D23 -> 2-yil | F3: =ProdPlan!E23 -> 3-yil | G3: =ProdPlan!F23 -> 4-yil | H3: =ProdPlan!G23 -> 5-yil | I3: =ProdPlan!H23 -> 6-yil | J3: =ProdPlan!I23 -> 7-yil
B4: Sotishdan tushgan tushum | C4: 0 | D4: =ProfLoss!C4 -> 357777000000 | E4: =ProfLoss!D4 -> 383332500000 | F4: =ProfLoss!E4 -> 408888000000 | G4: =ProfLoss!F4 -> 434443500000 | H4: =ProfLoss!G4 -> 459999000000 | I4: =ProfLoss!H4 -> 485554500000 | J4: =ProfLoss!I4 -> 511110000000
B5: =ProfLoss!B5 -> Налог на потребление ГСМ | C5: =(C4*120%)/20% -> 0 | D5: =ProfLoss!C5 -> 0 | E5: =ProfLoss!D5 -> 0 | F5: =ProfLoss!E5 -> 0 | G5: =ProfLoss!F5 -> 0
B7: Sotishdan tushgan naqd pul | C7: =C4-C6 -> 0 | D7: =D4-D5-D6 -> 357777000000 | E7: =E4-E5-E6 -> 383332500000 | F7: =F4-F5-F6 -> 408888000000 | G7: =G4-G5-G6 -> 434443500000 | H7: =H4-H5-H6 -> 459999000000 | I7: =I4-I5-I6 -> 485554500000 | J7: =J4-J5-J6 -> 511110000000
B8: Xizmatning bevosita xarajatlari | C8: 0 | D8: =CostSold!C10 -> 4.9110505e+09 | E8: =CostSold!D10 -> 4.9682133e+09 | F8: =CostSold!E10 -> 5.0253761e+09 | G8: =CostSold!F10 -> 5.0825389e+09 | H8: =CostSold!G10 -> 5.1397017e+09 | I8: =CostSold!H10 -> 5.1968645e+09 | J8: =CostSold!I10 -> 5.2540273e+09
B9: Yalpi pul tushumi | C9: =C7-C8 -> 0 | D9: =D7-D8 -> 3.5286595e+11 | E9: =E7-E8 -> 3.7836429e+11 | F9: =F7-F8 -> 4.0386262e+11 | G9: =G7-G8 -> 4.2936096e+11 | H9: =H7-H8 -> 4.548593e+11 | I9: =I7-I8 -> 4.8035764e+11 | J9: =J7-J8 -> 5.0585597e+11
B10: Amortizatsiya | C10: 0 | D10: =Depreciate!E7 -> 21714286 | E10: =Depreciate!F7 -> 21714286 | F10: =Depreciate!G7 -> 21714286 | G10: =Depreciate!H7 -> 21714286 | H10: =Depreciate!I7 -> 21714286 | I10: =Depreciate!J7 -> 21714286 | J10: =Depreciate!K7 -> 21714286
B11: Marketing xarajatlar | C11: 0 | D11: =CostSold!C15 -> 930220200 | E11: =CostSold!D15 -> 945553500 | F11: =CostSold!E15 -> 960886800 | G11: =CostSold!F15 -> 976220100 | H11: =CostSold!G15 -> 991553400 | I11: =CostSold!H15 -> 1006886700 | J11: =CostSold!I15 -> 1022220000
B12: Ma'muriy xarajatlar | C12: 0 | D12: =CostSold!C11+CostSold!C12 -> 16128000 | E12: =CostSold!D11+CostSold!D12 -> 16128000 | F12: =CostSold!E11+CostSold!E12 -> 16128000 | G12: =CostSold!F11+CostSold!F12 -> 16128000 | H12: =CostSold!G11+CostSold!G12 -> 16128000 | I12: =CostSold!H11+CostSold!H12 -> 16128000 | J12: =CostSold!I11+CostSold!I12 -> 16128000
B13: Boshqa xarajatlar | C13: 0 | D13: =ProfLoss!C11 -> 1737971600 | E13: =ProfLoss!D11 -> 1.7890859e+09 | F13: =ProfLoss!E11 -> 1.8402001e+09 | G13: =ProfLoss!F11 -> 1.8913144e+09 | H13: =ProfLoss!G11 -> 1.9424286e+09 | I13: =ProfLoss!H11 -> 1.9935429e+09 | J13: =ProfLoss!I11 -> 2.0446571e+09
B14: Operatsion pul oqimi | C14: =C9+C10-C11-C12-C13 -> 0 | D14: =D9-D11-D12-D13+D10 -> 350203343970 | E14: =E9-E11-E12-E13+E10 -> 3.7563523e+11 | F14: =F9-F11-F12-F13+F10 -> 4.0106712e+11 | G14: =G9-G11-G12-G13+G10 -> 4.2649901e+11 | H14: =H9-H11-H12-H13+H10 -> 4.519309e+11 | I14: =I9-I11-I12-I13+I10 -> 4.7736279e+11 | J14: =J9-J11-J12-J13+J10 -> 5.0279468e+11
B15: Собственные средства | C15: =FinPlan!E5 -> 52000000 | D15: 0
B16: Инвестиции в основной капитал | C16: ='Share of Costs'!G6 -> 150000000
B17: Финансовые издержки | C17: ='Share of Costs'!C10 -> 2000000
B18: Foiz to'lovlari | D18: =CostSold!C19 -> 18000000 | E18: =CostSold!D19 -> 18000000 | F18: =CostSold!E19 -> 17100000 | G18: =CostSold!F19 -> 13650000 | H18: =CostSold!G19 -> 10725000 | I18: =CostSold!H19 -> 6450000 | J18: =CostSold!I19 -> 2850000
B19: Soliqlar | C19: 0 | D19: =ProfLoss!C15+ProfLoss!C16 -> 14311080000 | E19: =ProfLoss!D15+ProfLoss!D16 -> 15333300000 | F19: =ProfLoss!E15+ProfLoss!E16 -> 16355520000 | G19: =ProfLoss!F15+ProfLoss!F16 -> 17377740000 | H19: =ProfLoss!G15+ProfLoss!G16 -> 18399960000 | I19: =ProfLoss!H15+ProfLoss!H16 -> 19422180000 | J19: =ProfLoss!I15+ProfLoss!I16 -> 20444400000
B20: Sof pul oqimi | C20: =C14+C15-C16-C17-C18-C19 -> -100000000 | D20: =D14+D15-D16-D17-D18-D19 -> 335874263970 | E20: =E14-E15-E16-E17-E18-E19 -> 3.6028393e+11 | F20: =F14-F15-F16-F17-F18-F19 -> 3.846945e+11 | G20: =G14-G15-G16-G17-G18-G19 -> 4.0910762e+11 | H20: =H14-H15-H16-H17-H18-H19 -> 4.3352022e+11 | I20: =I14-I15-I16-I17-I18-I19 -> 4.5793416e+11 | J20: =J14-J15-J16-J17-J18-J19 -> 4.8234743e+11
B22: Asosiy qarz to'lovi | D22: =SUM(Loans!C12:C23) -> 0 | E22: =SUM(Loans!C24:C35) -> 0 | F22: =SUM(Loans!C36:C47) -> 20000000 | G22: =SUM(Loans!C48:C59) -> 20000000 | H22: =SUM(Loans!C60:C71) -> 20000000 | I22: =SUM(Loans!C72:C83) -> 20000000 | J22: =SUM(Loans!C84:C95) -> 20000000
B23: Kredit to'langanidan keyin naqd pul | C23: =C20-C22 -> -100000000 | D23: =D20-D22 -> 335874263970 | E23: =E20-E22 -> 3.6028393e+11 | F23: =F20-F22 -> 3.846745e+11 | G23: =G20-G22 -> 4.0908762e+11 | H23: =H20-H22 -> 4.3350022e+11 | I23: =I20-I22 -> 4.5791416e+11 | J23: =J20-J22 -> 4.8232743e+11
B24: Moliyaviy so'rovlar | C24: =-C23 -> 100000000
B25: Поток наличности | C25: =C23+C24 -> 0 | D25: =D23-D24 -> 335874263970 | E25: =E23-E24 -> 3.6028393e+11 | F25: =F23-F24 -> 3.846745e+11 | G25: =G23-G24 -> 4.0908762e+11
B26: Kumulyatuv pul oqimi | C26: =C25 -> 0 | D26: =D23+C26 -> 335874263970 | E26: =E23+D26 -> 6.961582e+11 | F26: =F23+E26 -> 1.0808327e+12 | G26: =G23+F26 -> 1.4899203e+12 | H26: =H23+G26 -> 1.9234205e+12 | I26: =I23+H26 -> 2.3813347e+12 | J26: =J23+I26 -> 2.8636621e+12
B27: Xizmat ko'rsatish omili. Qarz | D27: - | E27: - | F27: =(F14-F19)/(F18+F22) -> 10369.585 | G27: =(G14-G19)/(G18+G22) -> 12158.136 | H27: =(H14-H19)/(H18+H22) -> 14110.039 | I27: =(I14-I19)/(I18+I22) -> 17313.445 | J27: =(J14-J19)/(J18+J22) -> 21109.422

Sheet npv
E3: 14-ILOVA
B4: Sof joriy qiymatni hisoblash
B5: YIL | C5: Sof pul oqimi | D5: 13,5% qayta moliyalash stavkasi bo'yicha chegirma koeffitsienti (o'rtacha tortilgan stavka) | E5: Pul oqimining joriy qiymati
B6: Investitsion xarajatlar | C6: =[2]ProjCost!F13*(-1) -> -408000000
B7: 1-yil | C7: =[2]CashFlow!D14 -> 243262530 | D7: =1/1.135 -> 0.88105727 | E7: =C7*D7 -> 2.1432822e+08
B8: 2-yil | C8: =+[2]CashFlow!E14 -> 253234584 | D8: =D7/1.135 -> 0.77626191 | E8: =C8*D8 -> 1.9657636e+08
B9: 3-yil | C9: =+[2]CashFlow!F14 -> 259882620 | D9: =D8/1.135 -> 0.6839312 | E9: =C9*D9 -> 1.7774183e+08
B10: 4-yil | C10: =+[2]CashFlow!G14 -> 276502710 | D10: =D9/1.135 -> 0.60258255 | E10: =C10*D10 -> 1.6661571e+08
B11: 5-yil | C11: =[2]CashFlow!H14 -> 293122800 | D11: =D10/1.135 -> 0.53090974 | E11: =C11*D11 -> 1.5562175e+08
B12: 6-yil | C12: =[2]CashFlow!I14 -> 0 | D12: =D11/1.135 -> 0.46776188 | E12: =C12*D12 -> 0
B13: 7-yil | E13: =C13*D13 -> 0
C14: Jami joriy qiymat | D14: JJQ | E14: =SUM(E7:E11) -> 9.1088387e+08
C15: Investitsion xarajatlar | D15: IX | E15: =C6 -> -408000000
C16: Sof joriy qiymatni hisoblash (SJQ=JJQ-IX) | D16: SJQ | E16: =E14+E15 -> 5.0288387e+08
C17: Investitsiyalar rentabelligi indeksini hisoblash IR=SJQ/IX+1 | D17: IR | E17: =E16/E15+1 -> -0.23255851
C18: Ichki daromad darajasi | D18: IDD | E18: =IRR(C6:C13,0.09) -> 0.55806793
C19: Investitsiyalarni qaytarish muddati diskontlangan pul oqimi loyihasi | D19: IQM | E19: =[2]Loans!D3 -> 60 oy
